Workbook

Sheet Read Me
B1: KPI Tracker: how this sheet works
B2: Built and refreshed by KPI Copilot 2.1.0. Every run updates this same sheet; what you typed in yellow cells is read back first and kept.
B4: Tabs
B5: Dashboard: totals per period and KPI results with coloured bars. Nothing to type here.
B6: Config: project details, counting rules, KPI targets, and the project dates used when a period or task has none.
B7: Periods: one row per KPI period with its dates, notes and PMS period ID.
B8: Task Register: every planned task and additional request, with the evidence behind each Yes/No.
B9: Defect Register: every bug, observation or improvement, including rejected ones.
B10: KPI Summary: the nine PMS KPIs per period, the facts behind each number, your reason, and the note that goes to PMS.
B11: Open Questions: what the sources could not answer. Answer in the yellow cell; the next run keeps it.
B12: Run Log: which sources this run read, which it did not, and how long it took.
B13: PMS Push Log: what was sent to PMS and when.
... B28: Initial Scope, Additional Requests 1, 2 ..., Milestone 1, 2 ..., Full Project (25 characters at most).

Sheet Dashboard
A1: ="KPI Dashboard: "&Config!$C$4
A2: ="PMS project "&Config!$C$6&" · Velocity in "&Config!$C$18&" · Data pulled 2026-09-18 · Everything here is calculated from the other tabs."
A4: Work and issues by period
A5: # | B5: Period | C5: Delivered | D5: Not delivered yet | E5: Planned tasks | F5: Additional requests | G5: Completed | H5: Issues reported | I5: Bugs counted | J5: Rejected | K5: Found after handover | L5: Reopened | M5: Client date | N5: Commit date | O5: Handed over | Q5: Delivered (green) vs not yet (grey) | R5: Bugs (red) vs other issues (orange)
A6: =IF($B6="","",ROW()-5) | B6: =IFERROR(INDEX(Periods!$B$5:$B$200,ROW()-5)&"","") | C6: =IF($B6="","",COUNTIFS('Task Register'!$B$4:$B$999,$B6,'Task Register'!$F$4:$F$999,"<>Excluded",'Task Register'!$M$4:$M$999,">0")) | D6: =IF($B6="","",COUNTIFS('Task Register'!$B$4:$B$999,$B6,'Task Register'!$F$4:$F$999,"<>Excluded")-COUNTIFS('Task Register'!$B$4:$B$999,$B6,'Task Register'!$F$4:$F$999,"<>Excluded",'Task Register'!$M$4:$M$999,">0")) | E6: =IF($B6="","",COUNTIFS('Task Register'!$B$4:$B$999,$B6,'Task Register'!$F$4:$F$999,"<>Excluded",'Task Register'!$G$4:$G$999,"Yes")) | F6: =IF($B6="","",COUNTIFS('Task Register'!$B$4:$B$999,$B6,'Task Register'!$F$4:$F$999,"CR")) | G6: =IF($B6="","",ROUND(SUMIFS('KPI Summary'!$E$4:$E$999,'KPI Summary'!$A$4:$A$999,$B6,'KPI Summary'!$C$4:$C$999,"Velocity"),2)&IF(Config!$C$18="Story Points"," pts"," h")) | H6: =IF($B6="","",COUNTIFS('Defect Register'!$B$4:$B$999,$B6)) | I6: =IF($B6="","",COUNTIFS('Defect Register'!$B$4:$B$999,$B6,'Defect Register'!$O$4:$O$999,"Yes")) | J6: =IF($B6="","",COUNTIFS('Defect Register'!$B$4:$B$999,$B6,'Defect Register'!$K$4:$K$999,"Yes")) | K6: =IF($B6="","",COUNTIFS('Defect Register'!$B$4:$B$999,$B6,'Defect Register'!$I$4:$I$999,"Post-release",'Defect Register'!$K$4:$K$999,"<>Yes")) | L6: =IF($B6="","",COUNTIFS('Task Register'!$B$4:$B$999,$B6,'Task Register'!$F$4:$F$999,"<>Excluded",'Task Register'!$AP$4:$AP$999,">0",'Task Register'!$Y$4:$Y$999,"Yes")) | M6: =IF($B6="","",IF(N(IFERROR(INDEX(Periods!$F$5:$F$200,MATCH($B6,Periods!$B$5:$B$200,0)),""))>0,TEXT(IFERROR(INDEX(Periods!$F$5:$F$200,MATCH($B6,Periods!$B$5:$B$200,0)),""),"mm/dd/yyyy"),IF(N(Config!$C$40)>0,TEXT(Config!$C$40,"mm/dd/yyyy"),"-"))) | N6: =IF($B6="","",IF(N(IFERROR(INDEX(Periods!$G$5:$G$200,MATCH($B6,Periods!$B$5:$B$200,0)),""))>0,TEXT(IFERROR(INDEX(Periods!$G$5:$G$200,MATCH($B6,Periods!$B$5:$B$200,0)),""),"mm/dd/yyyy"),IF(N(Config!$C$41)>0,TEXT(Config!$C$41,"mm/dd/yyyy"),"-"))) | O6: =IF($B6="","",IF(N(IFERROR(INDEX(Periods!$H$5:$H$200,MATCH($B6,Periods!$B$5:$B$200,0)),""))>0,TEXT(IFERROR(INDEX(Periods!$H$5:$H$200,MATCH($B6,Periods!$B$5:$B$200,0)),""),"mm/dd/yyyy"),"Not yet")) | Q6: =IF($B6="","",REPT("█",ROUND(N(C6)/MAX(1,$C$6:$C$17,$D$6:$D$17)*18,0))&REPT("░",ROUND(N(D6)/MAX(1,$C$6:$C$17,$D$6:$D$17)*18,0))) | R6: =IF($B6="","",REPT("█",ROUND(N(I6)/MAX(1,$H$6:$H$17)*18,0))&REPT("░",ROUND((N(H6)-N(I6))/MAX(1,$H$6:$H$17)*18,0)))
A7: =IF($B7="","",ROW()-5) | B7: =IFERROR(INDEX(Periods!$B$5:$B$200,ROW()-5)&"","") | C7: =IF($B7="","",COUNTIFS('Task Register'!$B$4:$B$999,$B7,'Task Register'!$F$4:$F$999,"<>Excluded",'Task Register'!$M$4:$M$999,">0")) | D7: =IF($B7="","",COUNTIFS('Task Register'!$B$4:$B$999,$B7,'Task Register'!$F$4:$F$999,"<>Excluded")-COUNTIFS('Task Register'!$B$4:$B$999,$B7,'Task Register'!$F$4:$F$999,"<>Excluded",'Task Register'!$M$4:$M$999,">0")) | E7: =IF($B7="","",COUNTIFS('Task Register'!$B$4:$B$999,$B7,'Task Register'!$F$4:$F$999,"<>Excluded",'Task Register'!$G$4:$G$999,"Yes")) | F7: =IF($B7="","",COUNTIFS('Task Register'!$B$4:$B$999,$B7,'Task Register'!$F$4:$F$999,"CR")) | G7: =IF($B7="","",ROUND(SUMIFS('KPI Summary'!$E$4:$E$999,'KPI Summary'!$A$4:$A$999,$B7,'KPI Summary'!$C$4:$C$999,"Velocity"),2)&IF(Config!$C$18="Story Points"," pts"," h")) | H7: =IF($B7="","",COUNTIFS('Defect Register'!$B$4:$B$999,$B7)) | I7: =IF($B7="","",COUNTIFS('Defect Register'!$B$4:$B$999,$B7,'Defect Register'!$O$4:$O$999,"Yes")) | J7: =IF($B7="","",COUNTIFS('Defect Register'!$B$4:$B$999,$B7,'Defect Register'!$K$4:$K$999,"Yes")) | K7: =IF($B7="","",COUNTIFS('Defect Register'!$B$4:$B$999,$B7,'Defect Register'!$I$4:$I$999,"Post-release",'Defect Register'!$K$4:$K$999,"<>Yes")) | L7: =IF($B7="","",COUNTIFS('Task Register'!$B$4:$B$999,$B7,'Task Register'!$F$4:$F$999,"<>Excluded",'Task Register'!$AP$4:$AP$999,">0",'Task Register'!$Y$4:$Y$999,"Yes")) | M7: =IF($B7="","",IF(N(IFERROR(INDEX(Periods!$F$5:$F$200,MATCH($B7,Periods!$B$5:$B$200,0)),""))>0,TEXT(IFERROR(INDEX(Periods!$F$5:$F$200,MATCH($B7,Periods!$B$5:$B$200,0)),""),"mm/dd/yyyy"),IF(N(Config!$C$40)>0,TEXT(Config!$C$40,"mm/dd/yyyy"),"-"))) | N7: =IF($B7="","",IF(N(IFERROR(INDEX(Periods!$G$5:$G$200,MATCH($B7,Periods!$B$5:$B$200,0)),""))>0,TEXT(IFERROR(INDEX(Periods!$G$5:$G$200,MATCH($B7,Periods!$B$5:$B$200,0)),""),"mm/dd/yyyy"),IF(N(Config!$C$41)>0,TEXT(Config!$C$41,"mm/dd/yyyy"),"-"))) | O7: =IF($B7="","",IF(N(IFERROR(INDEX(Periods!$H$5:$H$200,MATCH($B7,Periods!$B$5:$B$200,0)),""))>0,TEXT(IFERROR(INDEX(Periods!$H$5:$H$200,MATCH($B7,Periods!$B$5:$B$200,0)),""),"mm/dd/yyyy"),"Not yet")) | Q7: =IF($B7="","",REPT("█",ROUND(N(C7)/MAX(1,$C$6:$C$17,$D$6:$D$17)*18,0))&REPT("░",ROUND(N(D7)/MAX(1,$C$6:$C$17,$D$6:$D$17)*18,0))) | R7: =IF($B7="","",REPT("█",ROUND(N(I7)/MAX(1,$H$6:$H$17)*18,0))&REPT("░",ROUND((N(H7)-N(I7))/MAX(1,$H$6:$H$17)*18,0)))
A8: =IF($B8="","",ROW()-5) | B8: =IFERROR(INDEX(Periods!$B$5:$B$200,ROW()-5)&"","") | C8: =IF($B8="","",COUNTIFS('Task Register'!$B$4:$B$999,$B8,'Task Register'!$F$4:$F$999,"<>Excluded",'Task Register'!$M$4:$M$999,">0")) | D8: =IF($B8="","",COUNTIFS('Task Register'!$B$4:$B$999,$B8,'Task Register'!$F$4:$F$999,"<>Excluded")-COUNTIFS('Task Register'!$B$4:$B$999,$B8,'Task Register'!$F$4:$F$999,"<>Excluded",'Task Register'!$M$4:$M$999,">0")) | E8: =IF($B8="","",COUNTIFS('Task Register'!$B$4:$B$999,$B8,'Task Register'!$F$4:$F$999,"<>Excluded",'Task Register'!$G$4:$G$999,"Yes")) | F8: =IF($B8="","",COUNTIFS('Task Register'!$B$4:$B$999,$B8,'Task Register'!$F$4:$F$999,"CR")) | G8: =IF($B8="","",ROUND(SUMIFS('KPI Summary'!$E$4:$E$999,'KPI Summary'!$A$4:$A$999,$B8,'KPI Summary'!$C$4:$C$999,"Velocity"),2)&IF(Config!$C$18="Story Points"," pts"," h")) | H8: =IF($B8="","",COUNTIFS('Defect Register'!$B$4:$B$999,$B8)) | I8: =IF($B8="","",COUNTIFS('Defect Register'!$B$4:$B$999,$B8,'Defect Register'!$O$4:$O$999,"Yes")) | J8: =IF($B8="","",COUNTIFS('Defect Register'!$B$4:$B$999,$B8,'Defect Register'!$K$4:$K$999,"Yes")) | K8: =IF($B8="","",COUNTIFS('Defect Register'!$B$4:$B$999,$B8,'Defect Register'!$I$4:$I$999,"Post-release",'Defect Register'!$K$4:$K$999,"<>Yes")) | L8: =IF($B8="","",COUNTIFS('Task Register'!$B$4:$B$999,$B8,'Task Register'!$F$4:$F$999,"<>Excluded",'Task Register'!$AP$4:$AP$999,">0",'Task Register'!$Y$4:$Y$999,"Yes")) | M8: =IF($B8="","",IF(N(IFERROR(INDEX(Periods!$F$5:$F$200,MATCH($B8,Periods!$B$5:$B$200,0)),""))>0,TEXT(IFERROR(INDEX(Periods!$F$5:$F$200,MATCH($B8,Periods!$B$5:$B$200,0)),""),"mm/dd/yyyy"),IF(N(Config!$C$40)>0,TEXT(Config!$C$40,"mm/dd/yyyy"),"-"))) | N8: =IF($B8="","",IF(N(IFERROR(INDEX(Periods!$G$5:$G$200,MATCH($B8,Periods!$B$5:$B$200,0)),""))>0,TEXT(IFERROR(INDEX(Periods!$G$5:$G$200,MATCH($B8,Periods!$B$5:$B$200,0)),""),"mm/dd/yyyy"),IF(N(Config!$C$41)>0,TEXT(Config!$C$41,"mm/dd/yyyy"),"-"))) | O8: =IF($B8="","",IF(N(IFERROR(INDEX(Periods!$H$5:$H$200,MATCH($B8,Periods!$B$5:$B$200,0)),""))>0,TEXT(IFERROR(INDEX(Periods!$H$5:$H$200,MATCH($B8,Periods!$B$5:$B$200,0)),""),"mm/dd/yyyy"),"Not yet")) | Q8: =IF($B8="","",REPT("█",ROUND(N(C8)/MAX(1,$C$6:$C$17,$D$6:$D$17)*18,0))&REPT("░",ROUND(N(D8)/MAX(1,$C$6:$C$17,$D$6:$D$17)*18,0))) | R8: =IF($B8="","",REPT("█",ROUND(N(I8)/MAX(1,$H$6:$H$17)*18,0))&REPT("░",ROUND((N(H8)-N(I8))/MAX(1,$H$6:$H$17)*18,0)))
A9: =IF($B9="","",ROW()-5) | B9: =IFERROR(INDEX(Periods!$B$5:$B$200,ROW()-5)&"","") | C9: =IF($B9="","",COUNTIFS('Task Register'!$B$4:$B$999,$B9,'Task Register'!$F$4:$F$999,"<>Excluded",'Task Register'!$M$4:$M$999,">0")) | D9: =IF($B9="","",COUNTIFS('Task Register'!$B$4:$B$999,$B9,'Task Register'!$F$4:$F$999,"<>Excluded")-COUNTIFS('Task Register'!$B$4:$B$999,$B9,'Task Register'!$F$4:$F$999,"<>Excluded",'Task Register'!$M$4:$M$999,">0")) | E9: =IF($B9="","",COUNTIFS('Task Register'!$B$4:$B$999,$B9,'Task Register'!$F$4:$F$999,"<>Excluded",'Task Register'!$G$4:$G$999,"Yes")) | F9: =IF($B9="","",COUNTIFS('Task Register'!$B$4:$B$999,$B9,'Task Register'!$F$4:$F$999,"CR")) | G9: =IF($B9="","",ROUND(SUMIFS('KPI Summary'!$E$4:$E$999,'KPI Summary'!$A$4:$A$999,$B9,'KPI Summary'!$C$4:$C$999,"Velocity"),2)&IF(Config!$C$18="Story Points"," pts"," h")) | H9: =IF($B9="","",COUNTIFS('Defect Register'!$B$4:$B$999,$B9)) | I9: =IF($B9="","",COUNTIFS('Defect Register'!$B$4:$B$999,$B9,'Defect Register'!$O$4:$O$999,"Yes")) | J9: =IF($B9="","",COUNTIFS('Defect Register'!$B$4:$B$999,$B9,'Defect Register'!$K$4:$K$999,"Yes")) | K9: =IF($B9="","",COUNTIFS('Defect Register'!$B$4:$B$999,$B9,'Defect Register'!$I$4:$I$999,"Post-release",'Defect Register'!$K$4:$K$999,"<>Yes")) | L9: =IF($B9="","",COUNTIFS('Task Register'!$B$4:$B$999,$B9,'Task Register'!$F$4:$F$999,"<>Excluded",'Task Register'!$AP$4:$AP$999,">0",'Task Register'!$Y$4:$Y$999,"Yes")) | M9: =IF($B9="","",IF(N(IFERROR(INDEX(Periods!$F$5:$F$200,MATCH($B9,Periods!$B$5:$B$200,0)),""))>0,TEXT(IFERROR(INDEX(Periods!$F$5:$F$200,MATCH($B9,Periods!$B$5:$B$200,0)),""),"mm/dd/yyyy"),IF(N(Config!$C$40)>0,TEXT(Config!$C$40,"mm/dd/yyyy"),"-"))) | N9: =IF($B9="","",IF(N(IFERROR(INDEX(Periods!$G$5:$G$200,MATCH($B9,Periods!$B$5:$B$200,0)),""))>0,TEXT(IFERROR(INDEX(Periods!$G$5:$G$200,MATCH($B9,Periods!$B$5:$B$200,0)),""),"mm/dd/yyyy"),IF(N(Config!$C$41)>0,TEXT(Config!$C$41,"mm/dd/yyyy"),"-"))) | O9: =IF($B9="","",IF(N(IFERROR(INDEX(Periods!$H$5:$H$200,MATCH($B9,Periods!$B$5:$B$200,0)),""))>0,TEXT(IFERROR(INDEX(Periods!$H$5:$H$200,MATCH($B9,Periods!$B$5:$B$200,0)),""),"mm/dd/yyyy"),"Not yet")) | Q9: =IF($B9="","",REPT("█",ROUND(N(C9)/MAX(1,$C$6:$C$17,$D$6:$D$17)*18,0))&REPT("░",ROUND(N(D9)/MAX(1,$C$6:$C$17,$D$6:$D$17)*18,0))) | R9: =IF($B9="","",REPT("█",ROUND(N(I9)/MAX(1,$H$6:$H$17)*18,0))&REPT("░",ROUND((N(H9)-N(I9))/MAX(1,$H$6:$H$17)*18,0)))
A10: =IF($B10="","",ROW()-5) | B10: =IFERROR(INDEX(Periods!$B$5:$B$200,ROW()-5)&"","") | C10: =IF($B10="","",COUNTIFS('Task Register'!$B$4:$B$999,$B10,'Task Register'!$F$4:$F$999,"<>Excluded",'Task Register'!$M$4:$M$999,">0")) | D10: =IF($B10="","",COUNTIFS('Task Register'!$B$4:$B$999,$B10,'Task Register'!$F$4:$F$999,"<>Excluded")-COUNTIFS('Task Register'!$B$4:$B$999,$B10,'Task Register'!$F$4:$F$999,"<>Excluded",'Task Register'!$M$4:$M$999,">0")) | E10: =IF($B10="","",COUNTIFS('Task Register'!$B$4:$B$999,$B10,'Task Register'!$F$4:$F$999,"<>Excluded",'Task Register'!$G$4:$G$999,"Yes")) | F10: =IF($B10="","",COUNTIFS('Task Register'!$B$4:$B$999,$B10,'Task Register'!$F$4:$F$999,"CR")) | G10: =IF($B10="","",ROUND(SUMIFS('KPI Summary'!$E$4:$E$999,'KPI Summary'!$A$4:$A$999,$B10,'KPI Summary'!$C$4:$C$999,"Velocity"),2)&IF(Config!$C$18="Story Points"," pts"," h")) | H10: =IF($B10="","",COUNTIFS('Defect Register'!$B$4:$B$999,$B10)) | I10: =IF($B10="","",COUNTIFS('Defect Register'!$B$4:$B$999,$B10,'Defect Register'!$O$4:$O$999,"Yes")) | J10: =IF($B10="","",COUNTIFS('Defect Register'!$B$4:$B$999,$B10,'Defect Register'!$K$4:$K$999,"Yes")) | K10: =IF($B10="","",COUNTIFS('Defect Register'!$B$4:$B$999,$B10,'Defect Register'!$I$4:$I$999,"Post-release",'Defect Register'!$K$4:$K$999,"<>Yes")) | L10: =IF($B10="","",COUNTIFS('Task Register'!$B$4:$B$999,$B10,'Task Register'!$F$4:$F$999,"<>Excluded",'Task Register'!$AP$4:$AP$999,">0",'Task Register'!$Y$4:$Y$999,"Yes")) | M10: =IF($B10="","",IF(N(IFERROR(INDEX(Periods!$F$5:$F$200,MATCH($B10,Periods!$B$5:$B$200,0)),""))>0,TEXT(IFERROR(INDEX(Periods!$F$5:$F$200,MATCH($B10,Periods!$B$5:$B$200,0)),""),"mm/dd/yyyy"),IF(N(Config!$C$40)>0,TEXT(Config!$C$40,"mm/dd/yyyy"),"-"))) | N10: =IF($B10="","",IF(N(IFERROR(INDEX(Periods!$G$5:$G$200,MATCH($B10,Periods!$B$5:$B$200,0)),""))>0,TEXT(IFERROR(INDEX(Periods!$G$5:$G$200,MATCH($B10,Periods!$B$5:$B$200,0)),""),"mm/dd/yyyy"),IF(N(Config!$C$41)>0,TEXT(Config!$C$41,"mm/dd/yyyy"),"-"))) | O10: =IF($B10="","",IF(N(IFERROR(INDEX(Periods!$H$5:$H$200,MATCH($B10,Periods!$B$5:$B$200,0)),""))>0,TEXT(IFERROR(INDEX(Periods!$H$5:$H$200,MATCH($B10,Periods!$B$5:$B$200,0)),""),"mm/dd/yyyy"),"Not yet")) | Q10: =IF($B10="","",REPT("█",ROUND(N(C10)/MAX(1,$C$6:$C$17,$D$6:$D$17)*18,0))&REPT("░",ROUND(N(D10)/MAX(1,$C$6:$C$17,$D$6:$D$17)*18,0))) | R10: =IF($B10="","",REPT("█",ROUND(N(I10)/MAX(1,$H$6:$H$17)*18,0))&REPT("░",ROUND((N(H10)-N(I10))/MAX(1,$H$6:$H$17)*18,0)))
A11: =IF($B11="","",ROW()-5) | B11: =IFERROR(INDEX(Periods!$B$5:$B$200,ROW()-5)&"","") | C11: =IF($B11="","",COUNTIFS('Task Register'!$B$4:$B$999,$B11,'Task Register'!$F$4:$F$999,"<>Excluded",'Task Register'!$M$4:$M$999,">0")) | D11: =IF($B11="","",COUNTIFS('Task Register'!$B$4:$B$999,$B11,'Task Register'!$F$4:$F$999,"<>Excluded")-COUNTIFS('Task Register'!$B$4:$B$999,$B11,'Task Register'!$F$4:$F$999,"<>Excluded",'Task Register'!$M$4:$M$999,">0")) | E11: =IF($B11="","",COUNTIFS('Task Register'!$B$4:$B$999,$B11,'Task Register'!$F$4:$F$999,"<>Excluded",'Task Register'!$G$4:$G$999,"Yes")) | F11: =IF($B11="","",COUNTIFS('Task Register'!$B$4:$B$999,$B11,'Task Register'!$F$4:$F$999,"CR")) | G11: =IF($B11="","",ROUND(SUMIFS('KPI Summary'!$E$4:$E$999,'KPI Summary'!$A$4:$A$999,$B11,'KPI Summary'!$C$4:$C$999,"Velocity"),2)&IF(Config!$C$18="Story Points"," pts"," h")) | H11: =IF($B11="","",COUNTIFS('Defect Register'!$B$4:$B$999,$B11)) | I11: =IF($B11="","",COUNTIFS('Defect Register'!$B$4:$B$999,$B11,'Defect Register'!$O$4:$O$999,"Yes")) | J11: =IF($B11="","",COUNTIFS('Defect Register'!$B$4:$B$999,$B11,'Defect Register'!$K$4:$K$999,"Yes")) | K11: =IF($B11="","",COUNTIFS('Defect Register'!$B$4:$B$999,$B11,'Defect Register'!$I$4:$I$999,"Post-release",'Defect Register'!$K$4:$K$999,"<>Yes")) | L11: =IF($B11="","",COUNTIFS('Task Register'!$B$4:$B$999,$B11,'Task Register'!$F$4:$F$999,"<>Excluded",'Task Register'!$AP$4:$AP$999,">0",'Task Register'!$Y$4:$Y$999,"Yes")) | M11: =IF($B11="","",IF(N(IFERROR(INDEX(Periods!$F$5:$F$200,MATCH($B11,Periods!$B$5:$B$200,0)),""))>0,TEXT(IFERROR(INDEX(Periods!$F$5:$F$200,MATCH($B11,Periods!$B$5:$B$200,0)),""),"mm/dd/yyyy"),IF(N(Config!$C$40)>0,TEXT(Config!$C$40,"mm/dd/yyyy"),"-"))) | N11: =IF($B11="","",IF(N(IFERROR(INDEX(Periods!$G$5:$G$200,MATCH($B11,Periods!$B$5:$B$200,0)),""))>0,TEXT(IFERROR(INDEX(Periods!$G$5:$G$200,MATCH($B11,Periods!$B$5:$B$200,0)),""),"mm/dd/yyyy"),IF(N(Config!$C$41)>0,TEXT(Config!$C$41,"mm/dd/yyyy"),"-"))) | O11: =IF($B11="","",IF(N(IFERROR(INDEX(Periods!$H$5:$H$200,MATCH($B11,Periods!$B$5:$B$200,0)),""))>0,TEXT(IFERROR(INDEX(Periods!$H$5:$H$200,MATCH($B11,Periods!$B$5:$B$200,0)),""),"mm/dd/yyyy"),"Not yet")) | Q11: =IF($B11="","",REPT("█",ROUND(N(C11)/MAX(1,$C$6:$C$17,$D$6:$D$17)*18,0))&REPT("░",ROUND(N(D11)/MAX(1,$C$6:$C$17,$D$6:$D$17)*18,0))) | R11: =IF($B11="","",REPT("█",ROUND(N(I11)/MAX(1,$H$6:$H$17)*18,0))&REPT("░",ROUND((N(H11)-N(I11))/MAX(1,$H$6:$H$17)*18,0)))
A12: =IF($B12="","",ROW()-5) | B12: =IFERROR(INDEX(Periods!$B$5:$B$200,ROW()-5)&"","") | C12: =IF($B12="","",COUNTIFS('Task Register'!$B$4:$B$999,$B12,'Task Register'!$F$4:$F$999,"<>Excluded",'Task Register'!$M$4:$M$999,">0")) | D12: =IF($B12="","",COUNTIFS('Task Register'!$B$4:$B$999,$B12,'Task Register'!$F$4:$F$999,"<>Excluded")-COUNTIFS('Task Register'!$B$4:$B$999,$B12,'Task Register'!$F$4:$F$999,"<>Excluded",'Task Register'!$M$4:$M$999,">0")) | E12: =IF($B12="","",COUNTIFS('Task Register'!$B$4:$B$999,$B12,'Task Register'!$F$4:$F$999,"<>Excluded",'Task Register'!$G$4:$G$999,"Yes")) | F12: =IF($B12="","",COUNTIFS('Task Register'!$B$4:$B$999,$B12,'Task Register'!$F$4:$F$999,"CR")) | G12: =IF($B12="","",ROUND(SUMIFS('KPI Summary'!$E$4:$E$999,'KPI Summary'!$A$4:$A$999,$B12,'KPI Summary'!$C$4:$C$999,"Velocity"),2)&IF(Config!$C$18="Story Points"," pts"," h")) | H12: =IF($B12="","",COUNTIFS('Defect Register'!$B$4:$B$999,$B12)) | I12: =IF($B12="","",COUNTIFS('Defect Register'!$B$4:$B$999,$B12,'Defect Register'!$O$4:$O$999,"Yes")) | J12: =IF($B12="","",COUNTIFS('Defect Register'!$B$4:$B$999,$B12,'Defect Register'!$K$4:$K$999,"Yes")) | K12: =IF($B12="","",COUNTIFS('Defect Register'!$B$4:$B$999,$B12,'Defect Register'!$I$4:$I$999,"Post-release",'Defect Register'!$K$4:$K$999,"<>Yes")) | L12: =IF($B12="","",COUNTIFS('Task Register'!$B$4:$B$999,$B12,'Task Register'!$F$4:$F$999,"<>Excluded",'Task Register'!$AP$4:$AP$999,">0",'Task Register'!$Y$4:$Y$999,"Yes")) | M12: =IF($B12="","",IF(N(IFERROR(INDEX(Periods!$F$5:$F$200,MATCH($B12,Periods!$B$5:$B$200,0)),""))>0,TEXT(IFERROR(INDEX(Periods!$F$5:$F$200,MATCH($B12,Periods!$B$5:$B$200,0)),""),"mm/dd/yyyy"),IF(N(Config!$C$40)>0,TEXT(Config!$C$40,"mm/dd/yyyy"),"-"))) | N12: =IF($B12="","",IF(N(IFERROR(INDEX(Periods!$G$5:$G$200,MATCH($B12,Periods!$B$5:$B$200,0)),""))>0,TEXT(IFERROR(INDEX(Periods!$G$5:$G$200,MATCH($B12,Periods!$B$5:$B$200,0)),""),"mm/dd/yyyy"),IF(N(Config!$C$41)>0,TEXT(Config!$C$41,"mm/dd/yyyy"),"-"))) | O12: =IF($B12="","",IF(N(IFERROR(INDEX(Periods!$H$5:$H$200,MATCH($B12,Periods!$B$5:$B$200,0)),""))>0,TEXT(IFERROR(INDEX(Periods!$H$5:$H$200,MATCH($B12,Periods!$B$5:$B$200,0)),""),"mm/dd/yyyy"),"Not yet")) | Q12: =IF($B12="","",REPT("█",ROUND(N(C12)/MAX(1,$C$6:$C$17,$D$6:$D$17)*18,0))&REPT("░",ROUND(N(D12)/MAX(1,$C$6:$C$17,$D$6:$D$17)*18,0))) | R12: =IF($B12="","",REPT("█",ROUND(N(I12)/MAX(1,$H$6:$H$17)*18,0))&REPT("░",ROUND((N(H12)-N(I12))/MAX(1,$H$6:$H$17)*18,0)))
A13: =IF($B13="","",ROW()-5) | B13: =IFERROR(INDEX(Periods!$B$5:$B$200,ROW()-5)&"","") | C13: =IF($B13="","",COUNTIFS('Task Register'!$B$4:$B$999,$B13,'Task Register'!$F$4:$F$999,"<>Excluded",'Task Register'!$M$4:$M$999,">0")) | D13: =IF($B13="","",COUNTIFS('Task Register'!$B$4:$B$999,$B13,'Task Register'!$F$4:$F$999,"<>Excluded")-COUNTIFS('Task Register'!$B$4:$B$999,$B13,'Task Register'!$F$4:$F$999,"<>Excluded",'Task Register'!$M$4:$M$999,">0")) | E13: =IF($B13="","",COUNTIFS('Task Register'!$B$4:$B$999,$B13,'Task Register'!$F$4:$F$999,"<>Excluded",'Task Register'!$G$4:$G$999,"Yes")) | F13: =IF($B13="","",COUNTIFS('Task Register'!$B$4:$B$999,$B13,'Task Register'!$F$4:$F$999,"CR")) | G13: =IF($B13="","",ROUND(SUMIFS('KPI Summary'!$E$4:$E$999,'KPI Summary'!$A$4:$A$999,$B13,'KPI Summary'!$C$4:$C$999,"Velocity"),2)&IF(Config!$C$18="Story Points"," pts"," h")) | H13: =IF($B13="","",COUNTIFS('Defect Register'!$B$4:$B$999,$B13)) | I13: =IF($B13="","",COUNTIFS('Defect Register'!$B$4:$B$999,$B13,'Defect Register'!$O$4:$O$999,"Yes")) | J13: =IF($B13="","",COUNTIFS('Defect Register'!$B$4:$B$999,$B13,'Defect Register'!$K$4:$K$999,"Yes")) | K13: =IF($B13="","",COUNTIFS('Defect Register'!$B$4:$B$999,$B13,'Defect Register'!$I$4:$I$999,"Post-release",'Defect Register'!$K$4:$K$999,"<>Yes")) | L13: =IF($B13="","",COUNTIFS('Task Register'!$B$4:$B$999,$B13,'Task Register'!$F$4:$F$999,"<>Excluded",'Task Register'!$AP$4:$AP$999,">0",'Task Register'!$Y$4:$Y$999,"Yes")) | M13: =IF($B13="","",IF(N(IFERROR(INDEX(Periods!$F$5:$F$200,MATCH($B13,Periods!$B$5:$B$200,0)),""))>0,TEXT(IFERROR(INDEX(Periods!$F$5:$F$200,MATCH($B13,Periods!$B$5:$B$200,0)),""),"mm/dd/yyyy"),IF(N(Config!$C$40)>0,TEXT(Config!$C$40,"mm/dd/yyyy"),"-"))) | N13: =IF($B13="","",IF(N(IFERROR(INDEX(Periods!$G$5:$G$200,MATCH($B13,Periods!$B$5:$B$200,0)),""))>0,TEXT(IFERROR(INDEX(Periods!$G$5:$G$200,MATCH($B13,Periods!$B$5:$B$200,0)),""),"mm/dd/yyyy"),IF(N(Config!$C$41)>0,TEXT(Config!$C$41,"mm/dd/yyyy"),"-"))) | O13: =IF($B13="","",IF(N(IFERROR(INDEX(Periods!$H$5:$H$200,MATCH($B13,Periods!$B$5:$B$200,0)),""))>0,TEXT(IFERROR(INDEX(Periods!$H$5:$H$200,MATCH($B13,Periods!$B$5:$B$200,0)),""),"mm/dd/yyyy"),"Not yet")) | Q13: =IF($B13="","",REPT("█",ROUND(N(C13)/MAX(1,$C$6:$C$17,$D$6:$D$17)*18,0))&REPT("░",ROUND(N(D13)/MAX(1,$C$6:$C$17,$D$6:$D$17)*18,0))) | R13: =IF($B13="","",REPT("█",ROUND(N(I13)/MAX(1,$H$6:$H$17)*18,0))&REPT("░",ROUND((N(H13)-N(I13))/MAX(1,$H$6:$H$17)*18,0)))
A14: =IF($B14="","",ROW()-5) | B14: =IFERROR(INDEX(Periods!$B$5:$B$200,ROW()-5)&"","") | C14: =IF($B14="","",COUNTIFS('Task Register'!$B$4:$B$999,$B14,'Task Register'!$F$4:$F$999,"<>Excluded",'Task Register'!$M$4:$M$999,">0")) | D14: =IF($B14="","",COUNTIFS('Task Register'!$B$4:$B$999,$B14,'Task Register'!$F$4:$F$999,"<>Excluded")-COUNTIFS('Task Register'!$B$4:$B$999,$B14,'Task Register'!$F$4:$F$999,"<>Excluded",'Task Register'!$M$4:$M$999,">0")) | E14: =IF($B14="","",COUNTIFS('Task Register'!$B$4:$B$999,$B14,'Task Register'!$F$4:$F$999,"<>Excluded",'Task Register'!$G$4:$G$999,"Yes")) | F14: =IF($B14="","",COUNTIFS('Task Register'!$B$4:$B$999,$B14,'Task Register'!$F$4:$F$999,"CR")) | G14: =IF($B14="","",ROUND(SUMIFS('KPI Summary'!$E$4:$E$999,'KPI Summary'!$A$4:$A$999,$B14,'KPI Summary'!$C$4:$C$999,"Velocity"),2)&IF(Config!$C$18="Story Points"," pts"," h")) | H14: =IF($B14="","",COUNTIFS('Defect Register'!$B$4:$B$999,$B14)) | I14: =IF($B14="","",COUNTIFS('Defect Register'!$B$4:$B$999,$B14,'Defect Register'!$O$4:$O$999,"Yes")) | J14: =IF($B14="","",COUNTIFS('Defect Register'!$B$4:$B$999,$B14,'Defect Register'!$K$4:$K$999,"Yes")) | K14: =IF($B14="","",COUNTIFS('Defect Register'!$B$4:$B$999,$B14,'Defect Register'!$I$4:$I$999,"Post-release",'Defect Register'!$K$4:$K$999,"<>Yes")) | L14: =IF($B14="","",COUNTIFS('Task Register'!$B$4:$B$999,$B14,'Task Register'!$F$4:$F$999,"<>Excluded",'Task Register'!$AP$4:$AP$999,">0",'Task Register'!$Y$4:$Y$999,"Yes")) | M14: =IF($B14="","",IF(N(IFERROR(INDEX(Periods!$F$5:$F$200,MATCH($B14,Periods!$B$5:$B$200,0)),""))>0,TEXT(IFERROR(INDEX(Periods!$F$5:$F$200,MATCH($B14,Periods!$B$5:$B$200,0)),""),"mm/dd/yyyy"),IF(N(Config!$C$40)>0,TEXT(Config!$C$40,"mm/dd/yyyy"),"-"))) | N14: =IF($B14="","",IF(N(IFERROR(INDEX(Periods!$G$5:$G$200,MATCH($B14,Periods!$B$5:$B$200,0)),""))>0,TEXT(IFERROR(INDEX(Periods!$G$5:$G$200,MATCH($B14,Periods!$B$5:$B$200,0)),""),"mm/dd/yyyy"),IF(N(Config!$C$41)>0,TEXT(Config!$C$41,"mm/dd/yyyy"),"-"))) | O14: =IF($B14="","",IF(N(IFERROR(INDEX(Periods!$H$5:$H$200,MATCH($B14,Periods!$B$5:$B$200,0)),""))>0,TEXT(IFERROR(INDEX(Periods!$H$5:$H$200,MATCH($B14,Periods!$B$5:$B$200,0)),""),"mm/dd/yyyy"),"Not yet")) | Q14: =IF($B14="","",REPT("█",ROUND(N(C14)/MAX(1,$C$6:$C$17,$D$6:$D$17)*18,0))&REPT("░",ROUND(N(D14)/MAX(1,$C$6:$C$17,$D$6:$D$17)*18,0))) | R14: =IF($B14="","",REPT("█",ROUND(N(I14)/MAX(1,$H$6:$H$17)*18,0))&REPT("░",ROUND((N(H14)-N(I14))/MAX(1,$H$6:$H$17)*18,0)))
A15: =IF($B15="","",ROW()-5) | B15: =IFERROR(INDEX(Periods!$B$5:$B$200,ROW()-5)&"","") | C15: =IF($B15="","",COUNTIFS('Task Register'!$B$4:$B$999,$B15,'Task Register'!$F$4:$F$999,"<>Excluded",'Task Register'!$M$4:$M$999,">0")) | D15: =IF($B15="","",COUNTIFS('Task Register'!$B$4:$B$999,$B15,'Task Register'!$F$4:$F$999,"<>Excluded")-COUNTIFS('Task Register'!$B$4:$B$999,$B15,'Task Register'!$F$4:$F$999,"<>Excluded",'Task Register'!$M$4:$M$999,">0")) | E15: =IF($B15="","",COUNTIFS('Task Register'!$B$4:$B$999,$B15,'Task Register'!$F$4:$F$999,"<>Excluded",'Task Register'!$G$4:$G$999,"Yes")) | F15: =IF($B15="","",COUNTIFS('Task Register'!$B$4:$B$999,$B15,'Task Register'!$F$4:$F$999,"CR")) | G15: =IF($B15="","",ROUND(SUMIFS('KPI Summary'!$E$4:$E$999,'KPI Summary'!$A$4:$A$999,$B15,'KPI Summary'!$C$4:$C$999,"Velocity"),2)&IF(Config!$C$18="Story Points"," pts"," h")) | H15: =IF($B15="","",COUNTIFS('Defect Register'!$B$4:$B$999,$B15)) | I15: =IF($B15="","",COUNTIFS('Defect Register'!$B$4:$B$999,$B15,'Defect Register'!$O$4:$O$999,"Yes")) | J15: =IF($B15="","",COUNTIFS('Defect Register'!$B$4:$B$999,$B15,'Defect Register'!$K$4:$K$999,"Yes")) | K15: =IF($B15="","",COUNTIFS('Defect Register'!$B$4:$B$999,$B15,'Defect Register'!$I$4:$I$999,"Post-release",'Defect Register'!$K$4:$K$999,"<>Yes")) | L15: =IF($B15="","",COUNTIFS('Task Register'!$B$4:$B$999,$B15,'Task Register'!$F$4:$F$999,"<>Excluded",'Task Register'!$AP$4:$AP$999,">0",'Task Register'!$Y$4:$Y$999,"Yes")) | M15: =IF($B15="","",IF(N(IFERROR(INDEX(Periods!$F$5:$F$200,MATCH($B15,Periods!$B$5:$B$200,0)),""))>0,TEXT(IFERROR(INDEX(Periods!$F$5:$F$200,MATCH($B15,Periods!$B$5:$B$200,0)),""),"mm/dd/yyyy"),IF(N(Config!$C$40)>0,TEXT(Config!$C$40,"mm/dd/yyyy"),"-"))) | N15: =IF($B15="","",IF(N(IFERROR(INDEX(Periods!$G$5:$G$200,MATCH($B15,Periods!$B$5:$B$200,0)),""))>0,TEXT(IFERROR(INDEX(Periods!$G$5:$G$200,MATCH($B15,Periods!$B$5:$B$200,0)),""),"mm/dd/yyyy"),IF(N(Config!$C$41)>0,TEXT(Config!$C$41,"mm/dd/yyyy"),"-"))) | O15: =IF($B15="","",IF(N(IFERROR(INDEX(Periods!$H$5:$H$200,MATCH($B15,Periods!$B$5:$B$200,0)),""))>0,TEXT(IFERROR(INDEX(Periods!$H$5:$H$200,MATCH($B15,Periods!$B$5:$B$200,0)),""),"mm/dd/yyyy"),"Not yet")) | Q15: =IF($B15="","",REPT("█",ROUND(N(C15)/MAX(1,$C$6:$C$17,$D$6:$D$17)*18,0))&REPT("░",ROUND(N(D15)/MAX(1,$C$6:$C$17,$D$6:$D$17)*18,0))) | R15: =IF($B15="","",REPT("█",ROUND(N(I15)/MAX(1,$H$6:$H$17)*18,0))&REPT("░",ROUND((N(H15)-N(I15))/MAX(1,$H$6:$H$17)*18,0)))
A16: =IF($B16="","",ROW()-5) | B16: =IFERROR(INDEX(Periods!$B$5:$B$200,ROW()-5)&"","") | C16: =IF($B16="","",COUNTIFS('Task Register'!$B$4:$B$999,$B16,'Task Register'!$F$4:$F$999,"<>Excluded",'Task Register'!$M$4:$M$999,">0")) | D16: =IF($B16="","",COUNTIFS('Task Register'!$B$4:$B$999,$B16,'Task Register'!$F$4:$F$999,"<>Excluded")-COUNTIFS('Task Register'!$B$4:$B$999,$B16,'Task Register'!$F$4:$F$999,"<>Excluded",'Task Register'!$M$4:$M$999,">0")) | E16: =IF($B16="","",COUNTIFS('Task Register'!$B$4:$B$999,$B16,'Task Register'!$F$4:$F$999,"<>Excluded",'Task Register'!$G$4:$G$999,"Yes")) | F16: =IF($B16="","",COUNTIFS('Task Register'!$B$4:$B$999,$B16,'Task Register'!$F$4:$F$999,"CR")) | G16: =IF($B16="","",ROUND(SUMIFS('KPI Summary'!$E$4:$E$999,'KPI Summary'!$A$4:$A$999,$B16,'KPI Summary'!$C$4:$C$999,"Velocity"),2)&IF(Config!$C$18="Story Points"," pts"," h")) | H16: =IF($B16="","",COUNTIFS('Defect Register'!$B$4:$B$999,$B16)) | I16: =IF($B16="","",COUNTIFS('Defect Register'!$B$4:$B$999,$B16,'Defect Register'!$O$4:$O$999,"Yes")) | J16: =IF($B16="","",COUNTIFS('Defect Register'!$B$4:$B$999,$B16,'Defect Register'!$K$4:$K$999,"Yes")) | K16: =IF($B16="","",COUNTIFS('Defect Register'!$B$4:$B$999,$B16,'Defect Register'!$I$4:$I$999,"Post-release",'Defect Register'!$K$4:$K$999,"<>Yes")) | L16: =IF($B16="","",COUNTIFS('Task Register'!$B$4:$B$999,$B16,'Task Register'!$F$4:$F$999,"<>Excluded",'Task Register'!$AP$4:$AP$999,">0",'Task Register'!$Y$4:$Y$999,"Yes")) | M16: =IF($B16="","",IF(N(IFERROR(INDEX(Periods!$F$5:$F$200,MATCH($B16,Periods!$B$5:$B$200,0)),""))>0,TEXT(IFERROR(INDEX(Periods!$F$5:$F$200,MATCH($B16,Periods!$B$5:$B$200,0)),""),"mm/dd/yyyy"),IF(N(Config!$C$40)>0,TEXT(Config!$C$40,"mm/dd/yyyy"),"-"))) | N16: =IF($B16="","",IF(N(IFERROR(INDEX(Periods!$G$5:$G$200,MATCH($B16,Periods!$B$5:$B$200,0)),""))>0,TEXT(IFERROR(INDEX(Periods!$G$5:$G$200,MATCH($B16,Periods!$B$5:$B$200,0)),""),"mm/dd/yyyy"),IF(N(Config!$C$41)>0,TEXT(Config!$C$41,"mm/dd/yyyy"),"-"))) | O16: =IF($B16="","",IF(N(IFERROR(INDEX(Periods!$H$5:$H$200,MATCH($B16,Periods!$B$5:$B$200,0)),""))>0,TEXT(IFERROR(INDEX(Periods!$H$5:$H$200,MATCH($B16,Periods!$B$5:$B$200,0)),""),"mm/dd/yyyy"),"Not yet")) | Q16: =IF($B16="","",REPT("█",ROUND(N(C16)/MAX(1,$C$6:$C$17,$D$6:$D$17)*18,0))&REPT("░",ROUND(N(D16)/MAX(1,$C$6:$C$17,$D$6:$D$17)*18,0))) | R16: =IF($B16="","",REPT("█",ROUND(N(I16)/MAX(1,$H$6:$H$17)*18,0))&REPT("░",ROUND((N(H16)-N(I16))/MAX(1,$H$6:$H$17)*18,0)))
A17: =IF($B17="","",ROW()-5) | B17: =IFERROR(INDEX(Periods!$B$5:$B$200,ROW()-5)&"","") | C17: =IF($B17="","",COUNTIFS('Task Register'!$B$4:$B$999,$B17,'Task Register'!$F$4:$F$999,"<>Excluded",'Task Register'!$M$4:$M$999,">0")) | D17: =IF($B17="","",COUNTIFS('Task Register'!$B$4:$B$999,$B17,'Task Register'!$F$4:$F$999,"<>Excluded")-COUNTIFS('Task Register'!$B$4:$B$999,$B17,'Task Register'!$F$4:$F$999,"<>Excluded",'Task Register'!$M$4:$M$999,">0")) | E17: =IF($B17="","",COUNTIFS('Task Register'!$B$4:$B$999,$B17,'Task Register'!$F$4:$F$999,"<>Excluded",'Task Register'!$G$4:$G$999,"Yes")) | F17: =IF($B17="","",COUNTIFS('Task Register'!$B$4:$B$999,$B17,'Task Register'!$F$4:$F$999,"CR")) | G17: =IF($B17="","",ROUND(SUMIFS('KPI Summary'!$E$4:$E$999,'KPI Summary'!$A$4:$A$999,$B17,'KPI Summary'!$C$4:$C$999,"Velocity"),2)&IF(Config!$C$18="Story Points"," pts"," h")) | H17: =IF($B17="","",COUNTIFS('Defect Register'!$B$4:$B$999,$B17)) | I17: =IF($B17="","",COUNTIFS('Defect Register'!$B$4:$B$999,$B17,'Defect Register'!$O$4:$O$999,"Yes")) | J17: =IF($B17="","",COUNTIFS('Defect Register'!$B$4:$B$999,$B17,'Defect Register'!$K$4:$K$999,"Yes")) | K17: =IF($B17="","",COUNTIFS('Defect Register'!$B$4:$B$999,$B17,'Defect Register'!$I$4:$I$999,"Post-release",'Defect Register'!$K$4:$K$999,"<>Yes")) | L17: =IF($B17="","",COUNTIFS('Task Register'!$B$4:$B$999,$B17,'Task Register'!$F$4:$F$999,"<>Excluded",'Task Register'!$AP$4:$AP$999,">0",'Task Register'!$Y$4:$Y$999,"Yes")) | M17: =IF($B17="","",IF(N(IFERROR(INDEX(Periods!$F$5:$F$200,MATCH($B17,Periods!$B$5:$B$200,0)),""))>0,TEXT(IFERROR(INDEX(Periods!$F$5:$F$200,MATCH($B17,Periods!$B$5:$B$200,0)),""),"mm/dd/yyyy"),IF(N(Config!$C$40)>0,TEXT(Config!$C$40,"mm/dd/yyyy"),"-"))) | N17: =IF($B17="","",IF(N(IFERROR(INDEX(Periods!$G$5:$G$200,MATCH($B17,Periods!$B$5:$B$200,0)),""))>0,TEXT(IFERROR(INDEX(Periods!$G$5:$G$200,MATCH($B17,Periods!$B$5:$B$200,0)),""),"mm/dd/yyyy"),IF(N(Config!$C$41)>0,TEXT(Config!$C$41,"mm/dd/yyyy"),"-"))) | O17: =IF($B17="","",IF(N(IFERROR(INDEX(Periods!$H$5:$H$200,MATCH($B17,Periods!$B$5:$B$200,0)),""))>0,TEXT(IFERROR(INDEX(Periods!$H$5:$H$200,MATCH($B17,Periods!$B$5:$B$200,0)),""),"mm/dd/yyyy"),"Not yet")) | Q17: =IF($B17="","",REPT("█",ROUND(N(C17)/MAX(1,$C$6:$C$17,$D$6:$D$17)*18,0))&REPT("░",ROUND(N(D17)/MAX(1,$C$6:$C$17,$D$6:$D$17)*18,0))) | R17: =IF($B17="","",REPT("█",ROUND(N(I17)/MAX(1,$H$6:$H$17)*18,0))&REPT("░",ROUND((N(H17)-N(I17))/MAX(1,$H$6:$H$17)*18,0)))
B18: Total | C18: =SUM(C6:C17) | D18: =SUM(D6:D17) | E18: =SUM(E6:E17) | F18: =SUM(F6:F17) | H18: =SUM(H6:H17) | I18: =SUM(I6:I17) | J18: =SUM(J6:J17) | K18: =SUM(K6:K17) | L18: =SUM(L6:L17)
A20: KPI results by period (the bar is green when the KPI is met, red when not)
B21: KPI | C21: Target | D21: =IF($B$6="","",$B$6) | F21: =IF($B$7="","",$B$7) | H21: =IF($B$8="","",$B$8) | J21: =IF($B$9="","",$B$9) | L21: =IF($B$10="","",$B$10) | N21: =IF($B$11="","",$B$11)
B22: Velocity | C22: =IFERROR(IF(INDEX(Config!$E$29:$E$37,MATCH($B22,Config!$B$29:$B$37,0))="Min","at least ","at most ")&INDEX(Config!$F$29:$F$37,MATCH($B22,Config!$B$29:$B$37,0))&IF($B22="Velocity",""," %"),"") | D22: =IF(D$21="","",IF(COUNTIFS('KPI Summary'!$A$4:$A$999,D$21,'KPI Summary'!$C$4:$C$999,$B22,'KPI Summary'!$G$4:$G$999,">=0")=0,"not measured",SUMIFS('KPI Summary'!$G$4:$G$999,'KPI Summary'!$A$4:$A$999,D$21,'KPI Summary'!$C$4:$C$999,$B22))) | E22: =IF(ISNUMBER(D22),REPT("█",ROUND(MIN(D22,IF($B22="Velocity",MAX(1,N(D22),N(F22),N(H22),N(J22),N(L22),N(N22)),100))/IF($B22="Velocity",MAX(1,N(D22),N(F22),N(H22),N(J22),N(L22),N(N22)),100)*14,0)),"") | F22: =IF(F$21="","",IF(COUNTIFS('KPI Summary'!$A$4:$A$999,F$21,'KPI Summary'!$C$4:$C$999,$B22,'KPI Summary'!$G$4:$G$999,">=0")=0,"not measured",SUMIFS('KPI Summary'!$G$4:$G$999,'KPI Summary'!$A$4:$A$999,F$21,'KPI Summary'!$C$4:$C$999,$B22))) | G22: =IF(ISNUMBER(F22),REPT("█",ROUND(MIN(F22,IF($B22="Velocity",MAX(1,N(D22),N(F22),N(H22),N(J22),N(L22),N(N22)),100))/IF($B22="Velocity",MAX(1,N(D22),N(F22),N(H22),N(J22),N(L22),N(N22)),100)*14,0)),"") | H22: =IF(H$21="","",IF(COUNTIFS('KPI Summary'!$A$4:$A$999,H$21,'KPI Summary'!$C$4:$C$999,$B22,'KPI Summary'!$G$4:$G$999,">=0")=0,"not measured",SUMIFS('KPI Summary'!$G$4:$G$999,'KPI Summary'!$A$4:$A$999,H$21,'KPI Summary'!$C$4:$C$999,$B22))) | I22: =IF(ISNUMBER(H22),REPT("█",ROUND(MIN(H22,IF($B22="Velocity",MAX(1,N(D22),N(F22),N(H22),N(J22),N(L22),N(N22)),100))/IF($B22="Velocity",MAX(1,N(D22),N(F22),N(H22),N(J22),N(L22),N(N22)),100)*14,0)),"") | J22: =IF(J$21="","",IF(COUNTIFS('KPI Summary'!$A$4:$A$999,J$21,'KPI Summary'!$C$4:$C$999,$B22,'KPI Summary'!$G$4:$G$999,">=0")=0,"not measured",SUMIFS('KPI Summary'!$G$4:$G$999,'KPI Summary'!$A$4:$A$999,J$21,'KPI Summary'!$C$4:$C$999,$B22))) | K22: =IF(ISNUMBER(J22),REPT("█",ROUND(MIN(J22,IF($B22="Velocity",MAX(1,N(D22),N(F22),N(H22),N(J22),N(L22),N(N22)),100))/IF($B22="Velocity",MAX(1,N(D22),N(F22),N(H22),N(J22),N(L22),N(N22)),100)*14,0)),"") | L22: =IF(L$21="","",IF(COUNTIFS('KPI Summary'!$A$4:$A$999,L$21,'KPI Summary'!$C$4:$C$999,$B22,'KPI Summary'!$G$4:$G$999,">=0")=0,"not measured",SUMIFS('KPI Summary'!$G$4:$G$999,'KPI Summary'!$A$4:$A$999,L$21,'KPI Summary'!$C$4:$C$999,$B22))) | M22: =IF(ISNUMBER(L22),REPT("█",ROUND(MIN(L22,IF($B22="Velocity",MAX(1,N(D22),N(F22),N(H22),N(J22),N(L22),N(N22)),100))/IF($B22="Velocity",MAX(1,N(D22),N(F22),N(H22),N(J22),N(L22),N(N22)),100)*14,0)),"") | N22: =IF(N$21="","",IF(COUNTIFS('KPI Summary'!$A$4:$A$999,N$21,'KPI Summary'!$C$4:$C$999,$B22,'KPI Summary'!$G$4:$G$999,">=0")=0,"not measured",SUMIFS('KPI Summary'!$G$4:$G$999,'KPI Summary'!$A$4:$A$999,N$21,'KPI Summary'!$C$4:$C$999,$B22))) | O22: =IF(ISNUMBER(N22),REPT("█",ROUND(MIN(N22,IF($B22="Velocity",MAX(1,N(D22),N(F22),N(H22),N(J22),N(L22),N(N22)),100))/IF($B22="Velocity",MAX(1,N(D22),N(F22),N(H22),N(J22),N(L22),N(N22)),100)*14,0)),"") | T22: =IF(ISNUMBER(D22),IF(COUNTIFS('KPI Summary'!$A$4:$A$999,D$21,'KPI Summary'!$C$4:$C$999,$B22,'KPI Summary'!$J$4:$J$999,"Met")>0,1,0),"") | U22: =IF(ISNUMBER(F22),IF(COUNTIFS('KPI Summary'!$A$4:$A$999,F$21,'KPI Summary'!$C$4:$C$999,$B22,'KPI Summary'!$J$4:$J$999,"Met")>0,1,0),"") | V22: =IF(ISNUMBER(H22),IF(COUNTIFS('KPI Summary'!$A$4:$A$999,H$21,'KPI Summary'!$C$4:$C$999,$B22,'KPI Summary'!$J$4:$J$999,"Met")>0,1,0),"") | W22: =IF(ISNUMBER(J22),IF(COUNTIFS('KPI Summary'!$A$4:$A$999,J$21,'KPI Summary'!$C$4:$C$999,$B22,'KPI Summary'!$J$4:$J$999,"Met")>0,1,0),"") | X22: =IF(ISNUMBER(L22),IF(COUNTIFS('KPI Summary'!$A$4:$A$999,L$21,'KPI Summary'!$C$4:$C$999,$B22,'KPI Summary'!$J$4:$J$999,"Met")>0,1,0),"") | Y22: =IF(ISNUMBER(N22),IF(COUNTIFS('KPI Summary'!$A$4:$A$999,N$21,'KPI Summary'!$C$4:$C$999,$B22,'KPI Summary'!$J$4:$J$999,"Met")>0,1,0),"")
B23: Task Comprehension | C23: =IFERROR(IF(INDEX(Config!$E$29:$E$37,MATCH($B23,Config!$B$29:$B$37,0))="Min","at least ","at most ")&INDEX(Config!$F$29:$F$37,MATCH($B23,Config!$B$29:$B$37,0))&IF($B23="Velocity",""," %"),"") | D23: =IF(D$21="","",IF(COUNTIFS('KPI Summary'!$A$4:$A$999,D$21,'KPI Summary'!$C$4:$C$999,$B23,'KPI Summary'!$G$4:$G$999,">=0")=0,"not measured",SUMIFS('KPI Summary'!$G$4:$G$999,'KPI Summary'!$A$4:$A$999,D$21,'KPI Summary'!$C$4:$C$999,$B23))) | E23: =IF(ISNUMBER(D23),REPT("█",ROUND(MIN(D23,IF($B23="Velocity",MAX(1,N(D23),N(F23),N(H23),N(J23),N(L23),N(N23)),100))/IF($B23="Velocity",MAX(1,N(D23),N(F23),N(H23),N(J23),N(L23),N(N23)),100)*14,0)),"") | F23: =IF(F$21="","",IF(COUNTIFS('KPI Summary'!$A$4:$A$999,F$21,'KPI Summary'!$C$4:$C$999,$B23,'KPI Summary'!$G$4:$G$999,">=0")=0,"not measured",SUMIFS('KPI Summary'!$G$4:$G$999,'KPI Summary'!$A$4:$A$999,F$21,'KPI Summary'!$C$4:$C$999,$B23))) | G23: =IF(ISNUMBER(F23),REPT("█",ROUND(MIN(F23,IF($B23="Velocity",MAX(1,N(D23),N(F23),N(H23),N(J23),N(L23),N(N23)),100))/IF($B23="Velocity",MAX(1,N(D23),N(F23),N(H23),N(J23),N(L23),N(N23)),100)*14,0)),"") | H23: =IF(H$21="","",IF(COUNTIFS('KPI Summary'!$A$4:$A$999,H$21,'KPI Summary'!$C$4:$C$999,$B23,'KPI Summary'!$G$4:$G$999,">=0")=0,"not measured",SUMIFS('KPI Summary'!$G$4:$G$999,'KPI Summary'!$A$4:$A$999,H$21,'KPI Summary'!$C$4:$C$999,$B23))) | I23: =IF(ISNUMBER(H23),REPT("█",ROUND(MIN(H23,IF($B23="Velocity",MAX(1,N(D23),N(F23),N(H23),N(J23),N(L23),N(N23)),100))/IF($B23="Velocity",MAX(1,N(D23),N(F23),N(H23),N(J23),N(L23),N(N23)),100)*14,0)),"") | J23: =IF(J$21="","",IF(COUNTIFS('KPI Summary'!$A$4:$A$999,J$21,'KPI Summary'!$C$4:$C$999,$B23,'KPI Summary'!$G$4:$G$999,">=0")=0,"not measured",SUMIFS('KPI Summary'!$G$4:$G$999,'KPI Summary'!$A$4:$A$999,J$21,'KPI Summary'!$C$4:$C$999,$B23))) | K23: =IF(ISNUMBER(J23),REPT("█",ROUND(MIN(J23,IF($B23="Velocity",MAX(1,N(D23),N(F23),N(H23),N(J23),N(L23),N(N23)),100))/IF($B23="Velocity",MAX(1,N(D23),N(F23),N(H23),N(J23),N(L23),N(N23)),100)*14,0)),"") | L23: =IF(L$21="","",IF(COUNTIFS('KPI Summary'!$A$4:$A$999,L$21,'KPI Summary'!$C$4:$C$999,$B23,'KPI Summary'!$G$4:$G$999,">=0")=0,"not measured",SUMIFS('KPI Summary'!$G$4:$G$999,'KPI Summary'!$A$4:$A$999,L$21,'KPI Summary'!$C$4:$C$999,$B23))) | M23: =IF(ISNUMBER(L23),REPT("█",ROUND(MIN(L23,IF($B23="Velocity",MAX(1,N(D23),N(F23),N(H23),N(J23),N(L23),N(N23)),100))/IF($B23="Velocity",MAX(1,N(D23),N(F23),N(H23),N(J23),N(L23),N(N23)),100)*14,0)),"") | N23: =IF(N$21="","",IF(COUNTIFS('KPI Summary'!$A$4:$A$999,N$21,'KPI Summary'!$C$4:$C$999,$B23,'KPI Summary'!$G$4:$G$999,">=0")=0,"not measured",SUMIFS('KPI Summary'!$G$4:$G$999,'KPI Summary'!$A$4:$A$999,N$21,'KPI Summary'!$C$4:$C$999,$B23))) | O23: =IF(ISNUMBER(N23),REPT("█",ROUND(MIN(N23,IF($B23="Velocity",MAX(1,N(D23),N(F23),N(H23),N(J23),N(L23),N(N23)),100))/IF($B23="Velocity",MAX(1,N(D23),N(F23),N(H23),N(J23),N(L23),N(N23)),100)*14,0)),"") | T23: =IF(ISNUMBER(D23),IF(COUNTIFS('KPI Summary'!$A$4:$A$999,D$21,'KPI Summary'!$C$4:$C$999,$B23,'KPI Summary'!$J$4:$J$999,"Met")>0,1,0),"") | U23: =IF(ISNUMBER(F23),IF(COUNTIFS('KPI Summary'!$A$4:$A$999,F$21,'KPI Summary'!$C$4:$C$999,$B23,'KPI Summary'!$J$4:$J$999,"Met")>0,1,0),"") | V23: =IF(ISNUMBER(H23),IF(COUNTIFS('KPI Summary'!$A$4:$A$999,H$21,'KPI Summary'!$C$4:$C$999,$B23,'KPI Summary'!$J$4:$J$999,"Met")>0,1,0),"") | W23: =IF(ISNUMBER(J23),IF(COUNTIFS('KPI Summary'!$A$4:$A$999,J$21,'KPI Summary'!$C$4:$C$999,$B23,'KPI Summary'!$J$4:$J$999,"Met")>0,1,0),"") | X23: =IF(ISNUMBER(L23),IF(COUNTIFS('KPI Summary'!$A$4:$A$999,L$21,'KPI Summary'!$C$4:$C$999,$B23,'KPI Summary'!$J$4:$J$999,"Met")>0,1,0),"") | Y23: =IF(ISNUMBER(N23),IF(COUNTIFS('KPI Summary'!$A$4:$A$999,N$21,'KPI Summary'!$C$4:$C$999,$B23,'KPI Summary'!$J$4:$J$999,"Met")>0,1,0),"")
B24: Client Expectation | C24: =IFERROR(IF(INDEX(Config!$E$29:$E$37,MATCH($B24,Config!$B$29:$B$37,0))="Min","at least ","at most ")&INDEX(Config!$F$29:$F$37,MATCH($B24,Config!$B$29:$B$37,0))&IF($B24="Velocity",""," %"),"") | D24: =IF(D$21="","",IF(COUNTIFS('KPI Summary'!$A$4:$A$999,D$21,'KPI Summary'!$C$4:$C$999,$B24,'KPI Summary'!$G$4:$G$999,">=0")=0,"not measured",SUMIFS('KPI Summary'!$G$4:$G$999,'KPI Summary'!$A$4:$A$999,D$21,'KPI Summary'!$C$4:$C$999,$B24))) | E24: =IF(ISNUMBER(D24),REPT("█",ROUND(MIN(D24,IF($B24="Velocity",MAX(1,N(D24),N(F24),N(H24),N(J24),N(L24),N(N24)),100))/IF($B24="Velocity",MAX(1,N(D24),N(F24),N(H24),N(J24),N(L24),N(N24)),100)*14,0)),"") | F24: =IF(F$21="","",IF(COUNTIFS('KPI Summary'!$A$4:$A$999,F$21,'KPI Summary'!$C$4:$C$999,$B24,'KPI Summary'!$G$4:$G$999,">=0")=0,"not measured",SUMIFS('KPI Summary'!$G$4:$G$999,'KPI Summary'!$A$4:$A$999,F$21,'KPI Summary'!$C$4:$C$999,$B24))) | G24: =IF(ISNUMBER(F24),REPT("█",ROUND(MIN(F24,IF($B24="Velocity",MAX(1,N(D24),N(F24),N(H24),N(J24),N(L24),N(N24)),100))/IF($B24="Velocity",MAX(1,N(D24),N(F24),N(H24),N(J24),N(L24),N(N24)),100)*14,0)),"") | H24: =IF(H$21="","",IF(COUNTIFS('KPI Summary'!$A$4:$A$999,H$21,'KPI Summary'!$C$4:$C$999,$B24,'KPI Summary'!$G$4:$G$999,">=0")=0,"not measured",SUMIFS('KPI Summary'!$G$4:$G$999,'KPI Summary'!$A$4:$A$999,H$21,'KPI Summary'!$C$4:$C$999,$B24))) | I24: =IF(ISNUMBER(H24),REPT("█",ROUND(MIN(H24,IF($B24="Velocity",MAX(1,N(D24),N(F24),N(H24),N(J24),N(L24),N(N24)),100))/IF($B24="Velocity",MAX(1,N(D24),N(F24),N(H24),N(J24),N(L24),N(N24)),100)*14,0)),"") | J24: =IF(J$21="","",IF(COUNTIFS('KPI Summary'!$A$4:$A$999,J$21,'KPI Summary'!$C$4:$C$999,$B24,'KPI Summary'!$G$4:$G$999,">=0")=0,"not measured",SUMIFS('KPI Summary'!$G$4:$G$999,'KPI Summary'!$A$4:$A$999,J$21,'KPI Summary'!$C$4:$C$999,$B24))) | K24: =IF(ISNUMBER(J24),REPT("█",ROUND(MIN(J24,IF($B24="Velocity",MAX(1,N(D24),N(F24),N(H24),N(J24),N(L24),N(N24)),100))/IF($B24="Velocity",MAX(1,N(D24),N(F24),N(H24),N(J24),N(L24),N(N24)),100)*14,0)),"") | L24: =IF(L$21="","",IF(COUNTIFS('KPI Summary'!$A$4:$A$999,L$21,'KPI Summary'!$C$4:$C$999,$B24,'KPI Summary'!$G$4:$G$999,">=0")=0,"not measured",SUMIFS('KPI Summary'!$G$4:$G$999,'KPI Summary'!$A$4:$A$999,L$21,'KPI Summary'!$C$4:$C$999,$B24))) | M24: =IF(ISNUMBER(L24),REPT("█",ROUND(MIN(L24,IF($B24="Velocity",MAX(1,N(D24),N(F24),N(H24),N(J24),N(L24),N(N24)),100))/IF($B24="Velocity",MAX(1,N(D24),N(F24),N(H24),N(J24),N(L24),N(N24)),100)*14,0)),"") | N24: =IF(N$21="","",IF(COUNTIFS('KPI Summary'!$A$4:$A$999,N$21,'KPI Summary'!$C$4:$C$999,$B24,'KPI Summary'!$G$4:$G$999,">=0")=0,"not measured",SUMIFS('KPI Summary'!$G$4:$G$999,'KPI Summary'!$A$4:$A$999,N$21,'KPI Summary'!$C$4:$C$999,$B24))) | O24: =IF(ISNUMBER(N24),REPT("█",ROUND(MIN(N24,IF($B24="Velocity",MAX(1,N(D24),N(F24),N(H24),N(J24),N(L24),N(N24)),100))/IF($B24="Velocity",MAX(1,N(D24),N(F24),N(H24),N(J24),N(L24),N(N24)),100)*14,0)),"") | T24: =IF(ISNUMBER(D24),IF(COUNTIFS('KPI Summary'!$A$4:$A$999,D$21,'KPI Summary'!$C$4:$C$999,$B24,'KPI Summary'!$J$4:$J$999,"Met")>0,1,0),"") | U24: =IF(ISNUMBER(F24),IF(COUNTIFS('KPI Summary'!$A$4:$A$999,F$21,'KPI Summary'!$C$4:$C$999,$B24,'KPI Summary'!$J$4:$J$999,"Met")>0,1,0),"") | V24: =IF(ISNUMBER(H24),IF(COUNTIFS('KPI Summary'!$A$4:$A$999,H$21,'KPI Summary'!$C$4:$C$999,$B24,'KPI Summary'!$J$4:$J$999,"Met")>0,1,0),"") | W24: =IF(ISNUMBER(J24),IF(COUNTIFS('KPI Summary'!$A$4:$A$999,J$21,'KPI Summary'!$C$4:$C$999,$B24,'KPI Summary'!$J$4:$J$999,"Met")>0,1,0),"") | X24: =IF(ISNUMBER(L24),IF(COUNTIFS('KPI Summary'!$A$4:$A$999,L$21,'KPI Summary'!$C$4:$C$999,$B24,'KPI Summary'!$J$4:$J$999,"Met")>0,1,0),"") | Y24: =IF(ISNUMBER(N24),IF(COUNTIFS('KPI Summary'!$A$4:$A$999,N$21,'KPI Summary'!$C$4:$C$999,$B24,'KPI Summary'!$J$4:$J$999,"Met")>0,1,0),"")
B25: Delivery Commitment | C25: =IFERROR(IF(INDEX(Config!$E$29:$E$37,MATCH($B25,Config!$B$29:$B$37,0))="Min","at least ","at most ")&INDEX(Config!$F$29:$F$37,MATCH($B25,Config!$B$29:$B$37,0))&IF($B25="Velocity",""," %"),"") | D25: =IF(D$21="","",IF(COUNTIFS('KPI Summary'!$A$4:$A$999,D$21,'KPI Summary'!$C$4:$C$999,$B25,'KPI Summary'!$G$4:$G$999,">=0")=0,"not measured",SUMIFS('KPI Summary'!$G$4:$G$999,'KPI Summary'!$A$4:$A$999,D$21,'KPI Summary'!$C$4:$C$999,$B25))) | E25: =IF(ISNUMBER(D25),REPT("█",ROUND(MIN(D25,IF($B25="Velocity",MAX(1,N(D25),N(F25),N(H25),N(J25),N(L25),N(N25)),100))/IF($B25="Velocity",MAX(1,N(D25),N(F25),N(H25),N(J25),N(L25),N(N25)),100)*14,0)),"") | F25: =IF(F$21="","",IF(COUNTIFS('KPI Summary'!$A$4:$A$999,F$21,'KPI Summary'!$C$4:$C$999,$B25,'KPI Summary'!$G$4:$G$999,">=0")=0,"not measured",SUMIFS('KPI Summary'!$G$4:$G$999,'KPI Summary'!$A$4:$A$999,F$21,'KPI Summary'!$C$4:$C$999,$B25))) | G25: =IF(ISNUMBER(F25),REPT("█",ROUND(MIN(F25,IF($B25="Velocity",MAX(1,N(D25),N(F25),N(H25),N(J25),N(L25),N(N25)),100))/IF($B25="Velocity",MAX(1,N(D25),N(F25),N(H25),N(J25),N(L25),N(N25)),100)*14,0)),"") | H25: =IF(H$21="","",IF(COUNTIFS('KPI Summary'!$A$4:$A$999,H$21,'KPI Summary'!$C$4:$C$999,$B25,'KPI Summary'!$G$4:$G$999,">=0")=0,"not measured",SUMIFS('KPI Summary'!$G$4:$G$999,'KPI Summary'!$A$4:$A$999,H$21,'KPI Summary'!$C$4:$C$999,$B25))) | I25: =IF(ISNUMBER(H25),REPT("█",ROUND(MIN(H25,IF($B25="Velocity",MAX(1,N(D25),N(F25),N(H25),N(J25),N(L25),N(N25)),100))/IF($B25="Velocity",MAX(1,N(D25),N(F25),N(H25),N(J25),N(L25),N(N25)),100)*14,0)),"") | J25: =IF(J$21="","",IF(COUNTIFS('KPI Summary'!$A$4:$A$999,J$21,'KPI Summary'!$C$4:$C$999,$B25,'KPI Summary'!$G$4:$G$999,">=0")=0,"not measured",SUMIFS('KPI Summary'!$G$4:$G$999,'KPI Summary'!$A$4:$A$999,J$21,'KPI Summary'!$C$4:$C$999,$B25))) | K25: =IF(ISNUMBER(J25),REPT("█",ROUND(MIN(J25,IF($B25="Velocity",MAX(1,N(D25),N(F25),N(H25),N(J25),N(L25),N(N25)),100))/IF($B25="Velocity",MAX(1,N(D25),N(F25),N(H25),N(J25),N(L25),N(N25)),100)*14,0)),"") | L25: =IF(L$21="","",IF(COUNTIFS('KPI Summary'!$A$4:$A$999,L$21,'KPI Summary'!$C$4:$C$999,$B25,'KPI Summary'!$G$4:$G$999,">=0")=0,"not measured",SUMIFS('KPI Summary'!$G$4:$G$999,'KPI Summary'!$A$4:$A$999,L$21,'KPI Summary'!$C$4:$C$999,$B25))) | M25: =IF(ISNUMBER(L25),REPT("█",ROUND(MIN(L25,IF($B25="Velocity",MAX(1,N(D25),N(F25),N(H25),N(J25),N(L25),N(N25)),100))/IF($B25="Velocity",MAX(1,N(D25),N(F25),N(H25),N(J25),N(L25),N(N25)),100)*14,0)),"") | N25: =IF(N$21="","",IF(COUNTIFS('KPI Summary'!$A$4:$A$999,N$21,'KPI Summary'!$C$4:$C$999,$B25,'KPI Summary'!$G$4:$G$999,">=0")=0,"not measured",SUMIFS('KPI Summary'!$G$4:$G$999,'KPI Summary'!$A$4:$A$999,N$21,'KPI Summary'!$C$4:$C$999,$B25))) | O25: =IF(ISNUMBER(N25),REPT("█",ROUND(MIN(N25,IF($B25="Velocity",MAX(1,N(D25),N(F25),N(H25),N(J25),N(L25),N(N25)),100))/IF($B25="Velocity",MAX(1,N(D25),N(F25),N(H25),N(J25),N(L25),N(N25)),100)*14,0)),"") | T25: =IF(ISNUMBER(D25),IF(COUNTIFS('KPI Summary'!$A$4:$A$999,D$21,'KPI Summary'!$C$4:$C$999,$B25,'KPI Summary'!$J$4:$J$999,"Met")>0,1,0),"") | U25: =IF(ISNUMBER(F25),IF(COUNTIFS('KPI Summary'!$A$4:$A$999,F$21,'KPI Summary'!$C$4:$C$999,$B25,'KPI Summary'!$J$4:$J$999,"Met")>0,1,0),"") | V25: =IF(ISNUMBER(H25),IF(COUNTIFS('KPI Summary'!$A$4:$A$999,H$21,'KPI Summary'!$C$4:$C$999,$B25,'KPI Summary'!$J$4:$J$999,"Met")>0,1,0),"") | W25: =IF(ISNUMBER(J25),IF(COUNTIFS('KPI Summary'!$A$4:$A$999,J$21,'KPI Summary'!$C$4:$C$999,$B25,'KPI Summary'!$J$4:$J$999,"Met")>0,1,0),"") | X25: =IF(ISNUMBER(L25),IF(COUNTIFS('KPI Summary'!$A$4:$A$999,L$21,'KPI Summary'!$C$4:$C$999,$B25,'KPI Summary'!$J$4:$J$999,"Met")>0,1,0),"") | Y25: =IF(ISNUMBER(N25),IF(COUNTIFS('KPI Summary'!$A$4:$A$999,N$21,'KPI Summary'!$C$4:$C$999,$B25,'KPI Summary'!$J$4:$J$999,"Met")>0,1,0),"")
B26: Defect Rate | C26: =IFERROR(IF(INDEX(Config!$E$29:$E$37,MATCH($B26,Config!$B$29:$B$37,0))="Min","at least ","at most ")&INDEX(Config!$F$29:$F$37,MATCH($B26,Config!$B$29:$B$37,0))&IF($B26="Velocity",""," %"),"") | D26: =IF(D$21="","",IF(COUNTIFS('KPI Summary'!$A$4:$A$999,D$21,'KPI Summary'!$C$4:$C$999,$B26,'KPI Summary'!$G$4:$G$999,">=0")=0,"not measured",SUMIFS('KPI Summary'!$G$4:$G$999,'KPI Summary'!$A$4:$A$999,D$21,'KPI Summary'!$C$4:$C$999,$B26))) | E26: =IF(ISNUMBER(D26),REPT("█",ROUND(MIN(D26,IF($B26="Velocity",MAX(1,N(D26),N(F26),N(H26),N(J26),N(L26),N(N26)),100))/IF($B26="Velocity",MAX(1,N(D26),N(F26),N(H26),N(J26),N(L26),N(N26)),100)*14,0)),"") | F26: =IF(F$21="","",IF(COUNTIFS('KPI Summary'!$A$4:$A$999,F$21,'KPI Summary'!$C$4:$C$999,$B26,'KPI Summary'!$G$4:$G$999,">=0")=0,"not measured",SUMIFS('KPI Summary'!$G$4:$G$999,'KPI Summary'!$A$4:$A$999,F$21,'KPI Summary'!$C$4:$C$999,$B26))) | G26: =IF(ISNUMBER(F26),REPT("█",ROUND(MIN(F26,IF($B26="Velocity",MAX(1,N(D26),N(F26),N(H26),N(J26),N(L26),N(N26)),100))/IF($B26="Velocity",MAX(1,N(D26),N(F26),N(H26),N(J26),N(L26),N(N26)),100)*14,0)),"") | H26: =IF(H$21="","",IF(COUNTIFS('KPI Summary'!$A$4:$A$999,H$21,'KPI Summary'!$C$4:$C$999,$B26,'KPI Summary'!$G$4:$G$999,">=0")=0,"not measured",SUMIFS('KPI Summary'!$G$4:$G$999,'KPI Summary'!$A$4:$A$999,H$21,'KPI Summary'!$C$4:$C$999,$B26))) | I26: =IF(ISNUMBER(H26),REPT("█",ROUND(MIN(H26,IF($B26="Velocity",MAX(1,N(D26),N(F26),N(H26),N(J26),N(L26),N(N26)),100))/IF($B26="Velocity",MAX(1,N(D26),N(F26),N(H26),N(J26),N(L26),N(N26)),100)*14,0)),"") | J26: =IF(J$21="","",IF(COUNTIFS('KPI Summary'!$A$4:$A$999,J$21,'KPI Summary'!$C$4:$C$999,$B26,'KPI Summary'!$G$4:$G$999,">=0")=0,"not measured",SUMIFS('KPI Summary'!$G$4:$G$999,'KPI Summary'!$A$4:$A$999,J$21,'KPI Summary'!$C$4:$C$999,$B26))) | K26: =IF(ISNUMBER(J26),REPT("█",ROUND(MIN(J26,IF($B26="Velocity",MAX(1,N(D26),N(F26),N(H26),N(J26),N(L26),N(N26)),100))/IF($B26="Velocity",MAX(1,N(D26),N(F26),N(H26),N(J26),N(L26),N(N26)),100)*14,0)),"") | L26: =IF(L$21="","",IF(COUNTIFS('KPI Summary'!$A$4:$A$999,L$21,'KPI Summary'!$C$4:$C$999,$B26,'KPI Summary'!$G$4:$G$999,">=0")=0,"not measured",SUMIFS('KPI Summary'!$G$4:$G$999,'KPI Summary'!$A$4:$A$999,L$21,'KPI Summary'!$C$4:$C$999,$B26))) | M26: =IF(ISNUMBER(L26),REPT("█",ROUND(MIN(L26,IF($B26="Velocity",MAX(1,N(D26),N(F26),N(H26),N(J26),N(L26),N(N26)),100))/IF($B26="Velocity",MAX(1,N(D26),N(F26),N(H26),N(J26),N(L26),N(N26)),100)*14,0)),"") | N26: =IF(N$21="","",IF(COUNTIFS('KPI Summary'!$A$4:$A$999,N$21,'KPI Summary'!$C$4:$C$999,$B26,'KPI Summary'!$G$4:$G$999,">=0")=0,"not measured",SUMIFS('KPI Summary'!$G$4:$G$999,'KPI Summary'!$A$4:$A$999,N$21,'KPI Summary'!$C$4:$C$999,$B26))) | O26: =IF(ISNUMBER(N26),REPT("█",ROUND(MIN(N26,IF($B26="Velocity",MAX(1,N(D26),N(F26),N(H26),N(J26),N(L26),N(N26)),100))/IF($B26="Velocity",MAX(1,N(D26),N(F26),N(H26),N(J26),N(L26),N(N26)),100)*14,0)),"") | T26: =IF(ISNUMBER(D26),IF(COUNTIFS('KPI Summary'!$A$4:$A$999,D$21,'KPI Summary'!$C$4:$C$999,$B26,'KPI Summary'!$J$4:$J$999,"Met")>0,1,0),"") | U26: =IF(ISNUMBER(F26),IF(COUNTIFS('KPI Summary'!$A$4:$A$999,F$21,'KPI Summary'!$C$4:$C$999,$B26,'KPI Summary'!$J$4:$J$999,"Met")>0,1,0),"") | V26: =IF(ISNUMBER(H26),IF(COUNTIFS('KPI Summary'!$A$4:$A$999,H$21,'KPI Summary'!$C$4:$C$999,$B26,'KPI Summary'!$J$4:$J$999,"Met")>0,1,0),"") | W26: =IF(ISNUMBER(J26),IF(COUNTIFS('KPI Summary'!$A$4:$A$999,J$21,'KPI Summary'!$C$4:$C$999,$B26,'KPI Summary'!$J$4:$J$999,"Met")>0,1,0),"") | X26: =IF(ISNUMBER(L26),IF(COUNTIFS('KPI Summary'!$A$4:$A$999,L$21,'KPI Summary'!$C$4:$C$999,$B26,'KPI Summary'!$J$4:$J$999,"Met")>0,1,0),"") | Y26: =IF(ISNUMBER(N26),IF(COUNTIFS('KPI Summary'!$A$4:$A$999,N$21,'KPI Summary'!$C$4:$C$999,$B26,'KPI Summary'!$J$4:$J$999,"Met")>0,1,0),"")
B27: Escaped Defect Rate | C27: =IFERROR(IF(INDEX(Config!$E$29:$E$37,MATCH($B27,Config!$B$29:$B$37,0))="Min","at least ","at most ")&INDEX(Config!$F$29:$F$37,MATCH($B27,Config!$B$29:$B$37,0))&IF($B27="Velocity",""," %"),"") | D27: =IF(D$21="","",IF(COUNTIFS('KPI Summary'!$A$4:$A$999,D$21,'KPI Summary'!$C$4:$C$999,$B27,'KPI Summary'!$G$4:$G$999,">=0")=0,"not measured",SUMIFS('KPI Summary'!$G$4:$G$999,'KPI Summary'!$A$4:$A$999,D$21,'KPI Summary'!$C$4:$C$999,$B27))) | E27: =IF(ISNUMBER(D27),REPT("█",ROUND(MIN(D27,IF($B27="Velocity",MAX(1,N(D27),N(F27),N(H27),N(J27),N(L27),N(N27)),100))/IF($B27="Velocity",MAX(1,N(D27),N(F27),N(H27),N(J27),N(L27),N(N27)),100)*14,0)),"") | F27: =IF(F$21="","",IF(COUNTIFS('KPI Summary'!$A$4:$A$999,F$21,'KPI Summary'!$C$4:$C$999,$B27,'KPI Summary'!$G$4:$G$999,">=0")=0,"not measured",SUMIFS('KPI Summary'!$G$4:$G$999,'KPI Summary'!$A$4:$A$999,F$21,'KPI Summary'!$C$4:$C$999,$B27))) | G27: =IF(ISNUMBER(F27),REPT("█",ROUND(MIN(F27,IF($B27="Velocity",MAX(1,N(D27),N(F27),N(H27),N(J27),N(L27),N(N27)),100))/IF($B27="Velocity",MAX(1,N(D27),N(F27),N(H27),N(J27),N(L27),N(N27)),100)*14,0)),"") | H27: =IF(H$21="","",IF(COUNTIFS('KPI Summary'!$A$4:$A$999,H$21,'KPI Summary'!$C$4:$C$999,$B27,'KPI Summary'!$G$4:$G$999,">=0")=0,"not measured",SUMIFS('KPI Summary'!$G$4:$G$999,'KPI Summary'!$A$4:$A$999,H$21,'KPI Summary'!$C$4:$C$999,$B27))) | I27: =IF(ISNUMBER(H27),REPT("█",ROUND(MIN(H27,IF($B27="Velocity",MAX(1,N(D27),N(F27),N(H27),N(J27),N(L27),N(N27)),100))/IF($B27="Velocity",MAX(1,N(D27),N(F27),N(H27),N(J27),N(L27),N(N27)),100)*14,0)),"") | J27: =IF(J$21="","",IF(COUNTIFS('KPI Summary'!$A$4:$A$999,J$21,'KPI Summary'!$C$4:$C$999,$B27,'KPI Summary'!$G$4:$G$999,">=0")=0,"not measured",SUMIFS('KPI Summary'!$G$4:$G$999,'KPI Summary'!$A$4:$A$999,J$21,'KPI Summary'!$C$4:$C$999,$B27))) | K27: =IF(ISNUMBER(J27),REPT("█",ROUND(MIN(J27,IF($B27="Velocity",MAX(1,N(D27),N(F27),N(H27),N(J27),N(L27),N(N27)),100))/IF($B27="Velocity",MAX(1,N(D27),N(F27),N(H27),N(J27),N(L27),N(N27)),100)*14,0)),"") | L27: =IF(L$21="","",IF(COUNTIFS('KPI Summary'!$A$4:$A$999,L$21,'KPI Summary'!$C$4:$C$999,$B27,'KPI Summary'!$G$4:$G$999,">=0")=0,"not measured",SUMIFS('KPI Summary'!$G$4:$G$999,'KPI Summary'!$A$4:$A$999,L$21,'KPI Summary'!$C$4:$C$999,$B27))) | M27: =IF(ISNUMBER(L27),REPT("█",ROUND(MIN(L27,IF($B27="Velocity",MAX(1,N(D27),N(F27),N(H27),N(J27),N(L27),N(N27)),100))/IF($B27="Velocity",MAX(1,N(D27),N(F27),N(H27),N(J27),N(L27),N(N27)),100)*14,0)),"") | N27: =IF(N$21="","",IF(COUNTIFS('KPI Summary'!$A$4:$A$999,N$21,'KPI Summary'!$C$4:$C$999,$B27,'KPI Summary'!$G$4:$G$999,">=0")=0,"not measured",SUMIFS('KPI Summary'!$G$4:$G$999,'KPI Summary'!$A$4:$A$999,N$21,'KPI Summary'!$C$4:$C$999,$B27))) | O27: =IF(ISNUMBER(N27),REPT("█",ROUND(MIN(N27,IF($B27="Velocity",MAX(1,N(D27),N(F27),N(H27),N(J27),N(L27),N(N27)),100))/IF($B27="Velocity",MAX(1,N(D27),N(F27),N(H27),N(J27),N(L27),N(N27)),100)*14,0)),"") | T27: =IF(ISNUMBER(D27),IF(COUNTIFS('KPI Summary'!$A$4:$A$999,D$21,'KPI Summary'!$C$4:$C$999,$B27,'KPI Summary'!$J$4:$J$999,"Met")>0,1,0),"") | U27: =IF(ISNUMBER(F27),IF(COUNTIFS('KPI Summary'!$A$4:$A$999,F$21,'KPI Summary'!$C$4:$C$999,$B27,'KPI Summary'!$J$4:$J$999,"Met")>0,1,0),"") | V27: =IF(ISNUMBER(H27),IF(COUNTIFS('KPI Summary'!$A$4:$A$999,H$21,'KPI Summary'!$C$4:$C$999,$B27,'KPI Summary'!$J$4:$J$999,"Met")>0,1,0),"") | W27: =IF(ISNUMBER(J27),IF(COUNTIFS('KPI Summary'!$A$4:$A$999,J$21,'KPI Summary'!$C$4:$C$999,$B27,'KPI Summary'!$J$4:$J$999,"Met")>0,1,0),"") | X27: =IF(ISNUMBER(L27),IF(COUNTIFS('KPI Summary'!$A$4:$A$999,L$21,'KPI Summary'!$C$4:$C$999,$B27,'KPI Summary'!$J$4:$J$999,"Met")>0,1,0),"") | Y27: =IF(ISNUMBER(N27),IF(COUNTIFS('KPI Summary'!$A$4:$A$999,N$21,'KPI Summary'!$C$4:$C$999,$B27,'KPI Summary'!$J$4:$J$999,"Met")>0,1,0),"")
B28: Defect Rejection Rate | C28: =IFERROR(IF(INDEX(Config!$E$29:$E$37,MATCH($B28,Config!$B$29:$B$37,0))="Min","at least ","at most ")&INDEX(Config!$F$29:$F$37,MATCH($B28,Config!$B$29:$B$37,0))&IF($B28="Velocity",""," %"),"") | D28: =IF(D$21="","",IF(COUNTIFS('KPI Summary'!$A$4:$A$999,D$21,'KPI Summary'!$C$4:$C$999,$B28,'KPI Summary'!$G$4:$G$999,">=0")=0,"not measured",SUMIFS('KPI Summary'!$G$4:$G$999,'KPI Summary'!$A$4:$A$999,D$21,'KPI Summary'!$C$4:$C$999,$B28))) | E28: =IF(ISNUMBER(D28),REPT("█",ROUND(MIN(D28,IF($B28="Velocity",MAX(1,N(D28),N(F28),N(H28),N(J28),N(L28),N(N28)),100))/IF($B28="Velocity",MAX(1,N(D28),N(F28),N(H28),N(J28),N(L28),N(N28)),100)*14,0)),"") | F28: =IF(F$21="","",IF(COUNTIFS('KPI Summary'!$A$4:$A$999,F$21,'KPI Summary'!$C$4:$C$999,$B28,'KPI Summary'!$G$4:$G$999,">=0")=0,"not measured",SUMIFS('KPI Summary'!$G$4:$G$999,'KPI Summary'!$A$4:$A$999,F$21,'KPI Summary'!$C$4:$C$999,$B28))) | G28: =IF(ISNUMBER(F28),REPT("█",ROUND(MIN(F28,IF($B28="Velocity",MAX(1,N(D28),N(F28),N(H28),N(J28),N(L28),N(N28)),100))/IF($B28="Velocity",MAX(1,N(D28),N(F28),N(H28),N(J28),N(L28),N(N28)),100)*14,0)),"") | H28: =IF(H$21="","",IF(COUNTIFS('KPI Summary'!$A$4:$A$999,H$21,'KPI Summary'!$C$4:$C$999,$B28,'KPI Summary'!$G$4:$G$999,">=0")=0,"not measured",SUMIFS('KPI Summary'!$G$4:$G$999,'KPI Summary'!$A$4:$A$999,H$21,'KPI Summary'!$C$4:$C$999,$B28))) | I28: =IF(ISNUMBER(H28),REPT("█",ROUND(MIN(H28,IF($B28="Velocity",MAX(1,N(D28),N(F28),N(H28),N(J28),N(L28),N(N28)),100))/IF($B28="Velocity",MAX(1,N(D28),N(F28),N(H28),N(J28),N(L28),N(N28)),100)*14,0)),"") | J28: =IF(J$21="","",IF(COUNTIFS('KPI Summary'!$A$4:$A$999,J$21,'KPI Summary'!$C$4:$C$999,$B28,'KPI Summary'!$G$4:$G$999,">=0")=0,"not measured",SUMIFS('KPI Summary'!$G$4:$G$999,'KPI Summary'!$A$4:$A$999,J$21,'KPI Summary'!$C$4:$C$999,$B28))) | K28: =IF(ISNUMBER(J28),REPT("█",ROUND(MIN(J28,IF($B28="Velocity",MAX(1,N(D28),N(F28),N(H28),N(J28),N(L28),N(N28)),100))/IF($B28="Velocity",MAX(1,N(D28),N(F28),N(H28),N(J28),N(L28),N(N28)),100)*14,0)),"") | L28: =IF(L$21="","",IF(COUNTIFS('KPI Summary'!$A$4:$A$999,L$21,'KPI Summary'!$C$4:$C$999,$B28,'KPI Summary'!$G$4:$G$999,">=0")=0,"not measured",SUMIFS('KPI Summary'!$G$4:$G$999,'KPI Summary'!$A$4:$A$999,L$21,'KPI Summary'!$C$4:$C$999,$B28))) | M28: =IF(ISNUMBER(L28),REPT("█",ROUND(MIN(L28,IF($B28="Velocity",MAX(1,N(D28),N(F28),N(H28),N(J28),N(L28),N(N28)),100))/IF($B28="Velocity",MAX(1,N(D28),N(F28),N(H28),N(J28),N(L28),N(N28)),100)*14,0)),"") | N28: =IF(N$21="","",IF(COUNTIFS('KPI Summary'!$A$4:$A$999,N$21,'KPI Summary'!$C$4:$C$999,$B28,'KPI Summary'!$G$4:$G$999,">=0")=0,"not measured",SUMIFS('KPI Summary'!$G$4:$G$999,'KPI Summary'!$A$4:$A$999,N$21,'KPI Summary'!$C$4:$C$999,$B28))) | O28: =IF(ISNUMBER(N28),REPT("█",ROUND(MIN(N28,IF($B28="Velocity",MAX(1,N(D28),N(F28),N(H28),N(J28),N(L28),N(N28)),100))/IF($B28="Velocity",MAX(1,N(D28),N(F28),N(H28),N(J28),N(L28),N(N28)),100)*14,0)),"") | T28: =IF(ISNUMBER(D28),IF(COUNTIFS('KPI Summary'!$A$4:$A$999,D$21,'KPI Summary'!$C$4:$C$999,$B28,'KPI Summary'!$J$4:$J$999,"Met")>0,1,0),"") | U28: =IF(ISNUMBER(F28),IF(COUNTIFS('KPI Summary'!$A$4:$A$999,F$21,'KPI Summary'!$C$4:$C$999,$B28,'KPI Summary'!$J$4:$J$999,"Met")>0,1,0),"") | V28: =IF(ISNUMBER(H28),IF(COUNTIFS('KPI Summary'!$A$4:$A$999,H$21,'KPI Summary'!$C$4:$C$999,$B28,'KPI Summary'!$J$4:$J$999,"Met")>0,1,0),"") | W28: =IF(ISNUMBER(J28),IF(COUNTIFS('KPI Summary'!$A$4:$A$999,J$21,'KPI Summary'!$C$4:$C$999,$B28,'KPI Summary'!$J$4:$J$999,"Met")>0,1,0),"") | X28: =IF(ISNUMBER(L28),IF(COUNTIFS('KPI Summary'!$A$4:$A$999,L$21,'KPI Summary'!$C$4:$C$999,$B28,'KPI Summary'!$J$4:$J$999,"Met")>0,1,0),"") | Y28: =IF(ISNUMBER(N28),IF(COUNTIFS('KPI Summary'!$A$4:$A$999,N$21,'KPI Summary'!$C$4:$C$999,$B28,'KPI Summary'!$J$4:$J$999,"Met")>0,1,0),"")
